Workbook

Sheet Read Me
B2: MARA WATER: Premium-Only Restart Plan (KDQ), Oct 10 2026
B3: New workbook, built fresh from your latest instructions. This is not an edit of the old Reopening Plan file. It replaces its payroll, overheads, product mix, and restocking model with the ones below.
B5: What changed from the old plan
B6: Salaries: driver 20,000 / sales 20,000 / accountant-manager 25,000 / 6 production ladies at 10,000 each = 60,000. Payroll totals 125,000/month.
B7: Overheads: fuel 35,000 / electricity 10,000 / plumbing & repairs 6,000 / airtime 4,000 / miscellaneous 2,000 / parking & county fees 3,000 / printing-labels-stickers 6,000 (cut from 25,000 now that bottle labels are costed per bottle inside COGS, see point below). Overheads total 66,000/month.
B8: Jimal's operational stipend: 80,000/month by default, separate from hired payroll, paid before any profit is shared with Diana. A 65,000 alternative is modelled side by side throughout (New Team & Overheads, Starting Stock Section E, Weekly Restock Section F, and the Dashboard); it saves 15,000/month but is a small lever next to restock frequency.
B9: Total cash cost before profit share: 271,000/month at the 80,000 stipend, 256,000/month at the 65,000 stipend (125,000 payroll + 66,000 overheads + stipend). Transport is NOT in this figure; it is charged per trip, separately, since every order is a full lorry.
B10: Cost of production is now costed per bottle, by SKU: bottle/preform, label, seal and wrapper are each broken out and tabulated directly against COGS on the Starting Stock tab, using your exact per-bottle costings, not folded into a single guessed materials figure.
B11: Product mix: fully Premium, no Platinum, no Grace Resort. Custom Premium only, kept small. Refills continue since they carry no bottle cost.
B12: Ordering rule: every order, always, is one full lorry, 160,430 KES materials plus 45,000 transport, 205,430 total. Never a partial or scaled order.
B13: Target cadence: reorder once a week, full capacity each time, to ramp from one lorry up to a standing 800,000+ stock floor, funded by rolling sales cash rather than needing that much capital upfront. That is why the plan starts with just one lorry.
B14: Starting capital: 300,000 total: Jimal 200,000, Diana 100,000.
... B34: Blue text = input you can change. Black = formula. Green text = link to another tab in this workbook. Yellow fill = key assumption or headline result. Amber fill = a secondary or stretch scenario.

Sheet New Team & Overheads
B2: New team & overheads: monthly cost
B3: Every figure below is exactly what you specified. Blue = your input; edit these if a cost changes and everything downstream recalculates.
B5: A. PAYROLL
B6: Role | C6: People | D6: Pay each (KES) | E6: Monthly total (KES)
B7: Driver | C7: 1 | D7: 20000 | E7: =C7*D7 -> 20000
B8: Sales person | C8: 1 | D8: 20000 | E8: =C8*D8 -> 20000
B9: Accountant / manager | C9: 1 | D9: 25000 | E9: =C9*D9 -> 25000
B10: Production ladies | C10: 6 | D10: 10000 | E10: =C10*D10 -> 60000
B11: PAYROLL TOTAL | E11: =SUM(E7:E10) -> 125000
B13: B. MONTHLY OVERHEADS
B14: Item | E14: Monthly cost (KES)
B15: Fuel | E15: 35000
B16: Electricity | E16: 10000
B17: Plumbing & repairs | E17: 6000
B18: Airtime | E18: 4000
B19: Miscellaneous | E19: 2000
B20: Parking & county fees | E20: 3000
B21: Printing / labels / stickers (signage, invoices; bottle labels now costed per-bottle in COGS) | E21: 6000
B22: OVERHEADS TOTAL | E22: =SUM(E15:E21) -> 66000
B24: TOTAL FIXED MONTHLY COST (payroll + overheads) | E24: =E11+E22 -> 191000
B25: This total excludes transport (Nairobi to Rongo). Transport is charged per trip, not monthly, so it is modelled separately on the Restock Cadence tab where the trip count actually changes the answer.
B28: C. TRANSPORT (per trip, not monthly)
B29: Nairobi to Rongo, per trip | E29: 45000
B30: Full lorry load of bottles/materials | E30: 160000
B32: D. JIMAL'S OPERATIONAL STIPEND (pre-profit-share, not hired payroll)
B33: Jimal, on-ground operational manager, monthly stipend | E33: 80000
B34: This is separate from the hired-staff payroll in Section A. It is Jimal's own compensation for relocating to Rongo and running day-to-day operations full time, deducted from company cash before any profit is shared with Diana, exactly like a cost of running the business. See the Profit Sharing Model tab for how it fits into the full waterfall.
B36: 65,000 vs 80,000: dropping to 65,000 saves 15,000/month straight to net profit and moves the restock-frequency breakeven point slightly earlier (see the Starting Stock tab, Section E, for both figures side by side at every restock frequency, and the Weekly Restock tab, Section F, for how it moves the 300,000/500,000 profit targets). It is a real lever, but a small one next to restock frequency itself, which swings profit by well over 100,000/month. Keep 80,000 if it is what Jimal actually needs to live on while relocating; cut to 65,000 only if the household budget allows it, not primarily to fix the business's numbers.
B40: TOTAL CASH COST BEFORE PROFIT SHARE (payroll + overheads + stipend) | E40: =E24+E33 -> 271000

Sheet Premium-Only Mix vs September
B2: Premium-only mix vs September 2025 (what you keep, what you drop)
B3: September 2025 actual KDQ sales, all 16 SKUs, split by the new decision: fully Premium, no Platinum, no Grace, Custom Premium kept small. Green rows = kept in the new plan. Red rows = dropped.
B5: SKU | C5: Sold as | D5: Sept qty (bales/units) | E5: Pack size | F5: Cost/bottle (KES) | G5: Price/unit (KES) | H5: Sept revenue (KES) | I5: Sept materials cost (KES) | J5: Kept in new plan?
B6: Premium 500ml | C6: Bale | D6: 882 | E6: 24 | F6: 7.5025 | G6: 380 | H6: =D6*G6 -> 335160 | I6: =D6*E6*F6 -> 158812.92 | J6: KEPT
B7: Premium 1L | C7: Bale | D7: 176 | E7: 12 | F7: 12.675 | G7: 320 | H7: =D7*G7 -> 56320 | I7: =D7*E7*F7 -> 26769.6 | J7: KEPT
B8: Premium 1.5L | C8: Bale | D8: 492 | E8: 12 | F8: 16.1383 | G8: 410 | H8: =D8*G8 -> 201720 | I8: =D8*E8*F8 -> 95280.523 | J8: KEPT
B9: Premium 5L | C9: Unit | D9: 88 | E9: 1 | F9: 44.675 | G9: 95 | H9: =D9*G9 -> 8360 | I9: =D9*E9*F9 -> 3931.4 | J9: KEPT
B10: Premium 10L | C10: Unit | D10: 29 | E10: 1 | F10: 76.91 | G10: 165 | H10: =D10*G10 -> 4785 | I10: =D10*E10*F10 -> 2230.39 | J10: KEPT
B11: Premium 20L | C11: Unit | D11: 64 | E11: 1 | F11: 139.21 | G11: 295 | H11: =D11*G11 -> 18880 | I11: =D11*E11*F11 -> 8909.44 | J11: KEPT
B12: Platinum 500ml | C12: Bale | D12: 141 | E12: 24 | F12: 10.7825 | G12: 545 | H12: =D12*G12 -> 76845 | I12: =D12*E12*F12 -> 36487.98 | J12: DROPPED
B13: Platinum 1L | C13: Bale | D13: 3 | E13: 12 | F13: 19.645 | G13: 500 | H13: =D13*G13 -> 1500 | I13: =D13*E13*F13 -> 707.22 | J13: DROPPED
B14: Refill 5L | C14: Unit | D14: 21 | E14: 1 | F14: 0 | G14: 50 | H14: =D14*G14 -> 1050 | I14: =D14*E14*F14 -> 0 | J14: KEPT
B15: Refill 10L | C15: Unit | D15: 25 | E15: 1 | F15: 0 | G15: 120 | H15: =D15*G15 -> 3000 | I15: =D15*E15*F15 -> 0 | J15: KEPT
B16: Refill 20L | C16: Unit | D16: 143 | E16: 1 | F16: 0 | G16: 220 | H16: =D16*G16 -> 31460 | I16: =D16*E16*F16 -> 0 | J16: KEPT
B17: Custom 0.5L Prem | C17: Bale | D17: 43 | E17: 24 | F17: 7.5025 | G17: 380 | H17: =D17*G17 -> 16340 | I17: =D17*E17*F17 -> 7742.58 | J17: KEPT
... B21: Grace 1L | C21: Bale | D21: 30 | E21: 12 | F21: 12.675 | G21: 320 | H21: =D21*G21 -> 9600 | I21: =D21*E21*F21 -> 4563 | J21: DROPPED
B22: TOTAL: all 16 SKUs (Sept actual) | H22: =SUM(H6:H21) -> 898570.75 | I22: =SUM(I6:I21) -> 425124.71
B23: KEPT MIX TOTAL (new plan) | H23: =SUMIF(J6:J21,"KEPT",H6:H21) -> 677075 | I23: =SUMIF(J6:J21,"KEPT",I6:I21) -> 303676.85
B24: Kept-mix gross margin % | H24: =(H23-I23)/H23 -> 0.55148713
B25: Kept mix as % of Sept total revenue | H25: =H23/H22 -> 0.75350216
B27: September active selling days (out of 30) | D27: 20
B28: Kept-mix daily pace: revenue / materials cost per active day | H28: =H23/D27 -> 33853.75 | I28: =I23/D27 -> 15183.843
B30: Custom 0.5L Platinum and Custom 1L Platinum are dropped along with the rest of the Platinum line. Their September price above is back-solved (institutional pricing factor 0.7784x the standard Platinum bale price) purely so this table's totals reconcile to actual September revenue; it plays no role in the new plan since these SKUs are discontinued.

Sheet Starting Stock - Lorry & Profit
B2: Starting stock: the first 160,000 lorry, broken down by SKU
B3: Your 160,000 materials budget allocated across the kept SKUs by their share of September's kept-mix demand. Biggest sellers get the biggest share, Custom Premium stays deliberately small. Sold-out timing and per-SKU profit both come from real September pricing. Columns K onward break that materials cost down into its real components, from your Water_costings source.
B5: SKU | C5: Sold as | D5: Share of Sept demand | E5: Order qty (bales/units) | F5: Bottles | G5: Materials cost (KES) | H5: Projected revenue (KES) | I5: Projected profit (KES) | J5: Profit margin | K5: Bottle/preform (KES/bottle) | L5: Label (KES/bottle) | M5: Seal (KES/bottle) | N5: Wrapper (KES/bottle) | O5: Bottle/preform, this order (KES) | P5: Label, this order (KES) | Q5: Seal, this order (KES) | R5: Wrapper, this order (KES) | S5: Components total check (KES)
B6: Premium 500ml | C6: Bale (24pcs) | D6: 0.523 | E6: 465 | F6: =E6*24 -> 11160 | G6: 83727.9 | H6: 176700 | I6: =H6-G6 -> 92972.1 | J6: =I6/H6 -> 0.52615789 | K6: 5.87 | L6: 0.55 | M6: 0.27 | N6: 0.81 | O6: =K6*F6 -> 65509.2 | P6: =L6*F6 -> 6138 | Q6: =M6*F6 -> 3013.2 | R6: =N6*F6 -> 9039.6 | S6: =SUM(O6:R6) -> 83700
B7: Premium 1L | C7: Bale (12pcs) | D7: 0.0882 | E7: 93 | F7: =E7*12 -> 1116 | G7: 14145.3 | H7: 29760 | I7: =H7-G7 -> 15614.7 | J7: =I7/H7 -> 0.5246875 | K7: 9.73 | L7: 0.8 | M7: 0.27 | N7: 1.88 | O7: =K7*F7 -> 10858.68 | P7: =L7*F7 -> 892.8 | Q7: =M7*F7 -> 301.32 | R7: =N7*F7 -> 2098.08 | S7: =SUM(O7:R7) -> 14150.88
B8: Premium 1.5L | C8: Bale (12pcs) | D8: 0.3138 | E8: 260 | F8: =E8*12 -> 3120 | G8: 50351.59 | H8: 106600 | I8: =H8-G8 -> 56248.41 | J8: =I8/H8 -> 0.52765863 | K8: 12.96 | L8: 0.95 | M8: 0.27 | N8: 1.96 | O8: =K8*F8 -> 40435.2 | P8: =L8*F8 -> 2964 | Q8: =M8*F8 -> 842.4 | R8: =N8*F8 -> 6115.2 | S8: =SUM(O8:R8) -> 50356.8
B9: Premium 5L | C9: Unit | D9: 0.0129 | E9: 47 | F9: =E9*1 -> 47 | G9: 2099.72 | H9: 4465 | I9: =H9-G9 -> 2365.28 | J9: =I9/H9 -> 0.52973796 | K9: 35.3 | L9: 3 | M9: 0.5 | N9: 5.88 | O9: =K9*F9 -> 1659.1 | P9: =L9*F9 -> 141 | Q9: =M9*F9 -> 23.5 | R9: =N9*F9 -> 276.36 | S9: =SUM(O9:R9) -> 2099.96
B10: Premium 10L | C10: Unit | D10: 0.0073 | E10: 16 | F10: =E10*1 -> 16 | G10: 1230.56 | H10: 2640 | I10: =H10-G10 -> 1409.44 | J10: =I10/H10 -> 0.53387879 | K10: 73.1 | L10: 3 | M10: 0.81 | N10: 0 | O10: =K10*F10 -> 1169.6 | P10: =L10*F10 -> 48 | Q10: =M10*F10 -> 12.96 | R10: =N10*F10 -> 0 | S10: =SUM(O10:R10) -> 1230.56
B11: Premium 20L | C11: Unit | D11: 0.0293 | E11: 34 | F11: =E11*1 -> 34 | G11: 4733.14 | H11: 10030 | I11: =H11-G11 -> 5296.86 | J11: =I11/H11 -> 0.52810169 | K11: 135.4 | L11: 3 | M11: 0.81 | N11: 0 | O11: =K11*F11 -> 4603.6 | P11: =L11*F11 -> 102 | Q11: =M11*F11 -> 27.54 | R11: =N11*F11 -> 0 | S11: =SUM(O11:R11) -> 4733.14
B12: Custom 0.5L Prem | C12: Bale (24pcs) | D12: 0.0255 | E12: 23 | F12: =E12*24 -> 552 | G12: 4141.38 | H12: 8740 | I12: =H12-G12 -> 4598.62 | J12: =I12/H12 -> 0.52615789 | K12: 5.87 | L12: 0.55 | M12: 0.27 | N12: 0.81 | O12: =K12*F12 -> 3240.24 | P12: =L12*F12 -> 303.6 | Q12: =M12*F12 -> 149.04 | R12: =N12*F12 -> 447.12 | S12: =SUM(O12:R12) -> 4140
B13: SUBTOTAL: cost-bearing SKUs | F13: =SUM(F6:F12) -> 16045 | G13: =SUM(G6:G12) -> 160429.59 | H13: =SUM(H6:H12) -> 338935 | I13: =SUM(I6:I12) -> 178505.41 | J13: =I13/H13 -> 0.52666561 | O13: =SUM(O6:O12) -> 127475.62 | P13: =SUM(P6:P12) -> 10589.4 | Q13: =SUM(Q6:Q12) -> 4369.96 | R13: =SUM(R6:R12) -> 17976.36 | S13: =SUM(S6:S12) -> 160411.34
B14: Columns K to N are per-bottle component rates from your Water_costings source (bottle/preform, label, seal/bailing paper, wrapper/bale-wrap). Columns O to R multiply each by this order's bottle count, so they tie directly to the Materials cost in column G; column S is a reconciliation check and should equal column G on every row (small rounding only). 10L and 20L carry no wrapper cost since they are sold as single units, not baled.
B17: Refills carried alongside this lorry (customer's own container, zero bottle cost)
B18: SKU | E18: Est. units (lorry window) | H18: Projected revenue (KES)
B19: Refill 5L | E19: 11 | H19: =E19*50 -> 550
B20: Refill 10L | E20: 13 | H20: =E20*120 -> 1560
B21: Refill 20L | E21: 75 | H21: =E21*220 -> 16500
B22: REFILLS TOTAL | H22: =SUM(H19:H21) -> 18610
B24: GRAND TOTAL: this lorry's stock, fully sold | F24: =F13 -> 16045 | G24: =G13 -> 160429.59 | H24: =H13+H22 -> 357545 | I24: =H24-G24 -> 197115.41 | J24: =I24/H24 -> 0.55130238
B26: How long this lorry lasts at September's kept-mix daily pace | F26: ='Premium-Only Mix vs September'!I28 -> 15183.843 | G26: KES materials cost/day
B27: Lorry duration | F27: =G13/F26 -> 10.56581 | G27: selling days
B29: Order quantities are rounded up to whole bales/units, so the subtotal lands slightly above 160,000 (163k) rather than under. Better a few extra bales than running short mid-cycle. Premium 500ml and 1.5L together are about 84% of this order because they are September's proven volume drivers; Custom Premium is capped small on purpose, exactly as you asked.
B33: E. WHAT IF WE RESTOCK 1, 2, 3 OR 4 TIMES A MONTH (a full lorry every time)
B34: This corrects and replaces the draft you added in this area. Two things were missing there: VAT was not deducted, and the refill profit (pure profit, no bottle cost) was left out. Both are included below, and every column is a full lorry (never a partial order), scaled by how many times a month you send the truck.
B38: Measure | C38: 1 order/month | D38: 2 restocks/month | E38: 3 restocks/month | F38: 4 restocks/month
B39: Revenue (N full lorries) | C39: =1*$H$24 -> 357545 | D39: =2*$H$24 -> 715090 | E39: =3*$H$24 -> 1072635 | F39: =4*$H$24 -> 1430180
B40: Materials cost (N full lorries) | C40: =1*$G$24 -> 160429.59 | D40: =2*$G$24 -> 320859.18 | E40: =3*$G$24 -> 481288.77 | F40: =4*$G$24 -> 641718.36
B41: Gross trading margin | C41: =C39-C40 -> 197115.41 | D41: =D39-D40 -> 394230.82 | E41: =E39-E40 -> 591346.23 | F41: =F39-F40 -> 788461.64
B42: Net VAT payable (margin x 0.16/1.16) | C42: =C41*0.16/1.16 -> 27188.332 | D42: =D41*0.16/1.16 -> 54376.665 | E42: =E41*0.16/1.16 -> 81564.997 | F42: =F41*0.16/1.16 -> 108753.33
B43: Gross profit after VAT | C43: =C41-C42 -> 169927.08 | D43: =D41-D42 -> 339854.16 | E43: =E41-E42 -> 509781.23 | F43: =F41-F42 -> 679708.31
B44: Transport (45,000 per restock) | C44: =1*45000 -> 45000 | D44: =2*45000 -> 90000 | E44: =3*45000 -> 135000 | F44: =4*45000 -> 180000
B45: Fixed costs (payroll + overheads), from Team & Overheads | C45: ='New Team & Overheads'!E24 -> 191000 | D45: ='New Team & Overheads'!E24 -> 191000 | E45: ='New Team & Overheads'!E24 -> 191000 | F45: ='New Team & Overheads'!E24 -> 191000
B46: Jimal's stipend at 80,000 | C46: ='New Team & Overheads'!E33 -> 80000 | D46: ='New Team & Overheads'!E33 -> 80000 | E46: ='New Team & Overheads'!E33 -> 80000 | F46: ='New Team & Overheads'!E33 -> 80000
B47: NET PROFIT at 80,000 stipend | C47: =C43-C44-C45-C46 -> -146072.92 | D47: =D43-D44-D45-D46 -> -21145.845 | E47: =E43-E44-E45-E46 -> 103781.23 | F47: =F43-F44-F45-F46 -> 228708.31
B48: Jimal's stipend at 65,000 (alternative) | C48: 65000 | D48: 65000 | E48: 65000 | F48: 65000
B49: NET PROFIT at 65,000 stipend | C49: =C43-C44-C45-C48 -> -131072.92 | D49: =D43-D44-D45-D48 -> -6145.8448 | E49: =E43-E44-E45-E48 -> 118781.23 | F49: =F43-F44-F45-F48 -> 243708.31
B51: Breakeven sits between 2 and 3 restocks a month at either stipend level (about 2.05 lorries/month at 65,000, about 2.17 at 80,000). Two restocks a month is a real loss at both stipend levels; three is a solid profit; four is materially better again, but four lorries a month needs sales at roughly 1.76x September's proven pace and outpaces what 6 production ladies can currently process (see the Production Capacity and Weekly Restock tabs). Treat 3 restocks/month as the realistic near-term target and 4 as the growth goal once sales and staffing catch up.

Sheet Weekly Restock & Monthly P&L
B2: Weekly restock model: full lorry every week, toward the 800,000 floor
B3: Your committed model: never a partial order, always a full lorry, reordered weekly, funding the ramp from one lorry to a standing 800,000+ stock floor. Fixed costs, your stipend and VAT are deducted once, at month end, never weekly.
B5: A. THE RULE
B6: Every order, always, is one full lorry: 160,430 KES of materials plus the 45,000 transport fee, 205,430 total. No partial or scaled orders. Target cadence is once a week. Payroll, overheads and your stipend (298,190 combined once VAT-adjusted profit is known) are a single deduction at month end, not a weekly cost, so a thin week is not itself a crisis; the health check that matters is whether stock is actually selling through fast enough to justify buying the next one.
B10: B. WEEKLY CYCLE TRACKER, first 6 weeks (starting capital 300,000)
B11: Week | C11: Lorry outlay (KES) | D11: This week's sales at proven Sept pace | E11: Cumulative stock bought (KES) | F11: Running cash position (KES)
B12: Week 1 | C12: -205429.59 | D12: 203122.5 | E12: =C12*-1 -> 205429.59 | F12: =300000+C12+D12 -> 297692.91
B13: Week 2 | C13: =-205429.59 -> -205429.59 | D13: 203122.5 | E13: =E12+C13*-1 -> 410859.18 | F13: =F12+C13+D13 -> 295385.82
B14: Week 3 | C14: =-205429.59 -> -205429.59 | D14: 203122.5 | E14: =E13+C14*-1 -> 616288.77 | F14: =F13+C14+D14 -> 293078.73
B15: Week 4 | C15: =-205429.59 -> -205429.59 | D15: 203122.5 | E15: =E14+C15*-1 -> 821718.36 | F15: =F14+C15+D15 -> 290771.64
B16: Week 5 | C16: =-205429.59 -> -205429.59 | D16: 203122.5 | E16: =E15+C16*-1 -> 1027148 | F16: =F15+C16+D16 -> 288464.55
B17: Week 6 | C17: =-205429.59 -> -205429.59 | D17: 203122.5 | E17: =E16+C17*-1 -> 1232577.5 | F17: =F16+C17+D17 -> 286157.46
B19: Cash stays roughly stable week to week (each lorry costs slightly more than a week of proven-pace sales brings in, about a 2,300 KES/week gap) because the starting capital absorbs the difference. The real constraint is not cash running out, it is that ordering a full lorry every week outpaces what September's proven sales pace can actually sell through in a week, so unsold stock accumulates in the warehouse. That accumulation is exactly how you build toward the 800,000 floor, but it means month 1's accounting profit looks thinner than the cash position suggests, see Section D.
B23: C. REALITY CHECK: WHAT WEEKLY FULL-LORRY ORDERS REQUIRE
B24: Measure | D24: Value
B25: One lorry, full sellthrough, projected revenue | E25: 357545
B26: Proven Sept pace, revenue per 6-operating-day week | E26: 203122
B27: Sales pace needed vs proven, to sell a full lorry every week | E27: =E25/E26 -> 1.7602475
B29: Lorry sellout time at proven pace (days) | E29: 10.5
B30: 6 ladies' time to process a full lorry (days, from Production Capacity tab) | E30: ='Production Capacity - 6 Ladies'!D29 -> 15.457991
B32: 176% of proven pace is what weekly full-lorry sellthrough actually requires, and production (about 15.5 days to process one lorry) is slower still. Ordering weekly from week one assumes both sales and production scale up substantially beyond what has been demonstrated. That is a fine target to plan toward, but it should be an explicit growth goal, not a silent assumption baked into the P&L.
B36: D. MONTHLY P&L, TWO SCENARIOS
B37: Line item | C37: Target: sales scale to match weekly full lorries | D37: Reality check: proven Sept pace, ordered weekly
B38: Revenue | C38: 1549362 | D38: 880198
B39: Materials cost of goods SOLD | C39: 695195 | D39: 394780
B40: Gross trading margin | C40: =C38-C39 -> 854167 | D40: =D38-D39 -> 485418
B41: Net VAT payable (margin x 0.16/1.16) | C41: =C40*0.16/1.16 -> 117816.14 | D41: =D40*0.16/1.16 -> 66954.207
B42: Gross profit after VAT | C42: =C40-C41 -> 736350.86 | D42: =D40-D41 -> 418463.79
B43: Transport (4.33 lorries/trips this month) | C43: 195000 | D43: 195000
B44: Fixed costs (payroll + overheads), paid once at month end | C44: ='New Team & Overheads'!E24 -> 191000 | D44: ='New Team & Overheads'!E24 -> 191000
B45: Jimal's operational stipend, paid once at month end | C45: ='New Team & Overheads'!E33 -> 80000 | D45: ='New Team & Overheads'!E33 -> 80000
B46: NET COMPANY PROFIT (pre profit-share) | C46: =C42-C43-C44-C45 -> 270350.86 | D46: =D42-D43-D44-D45 -> -47536.207
B47: Unsold stock accumulating in warehouse this month (cost basis) | C47: 0 | D47: =4.333*160429.59-D39 -> 300361.41
B49: The target column is what the plan needs to become true: sales growing to about 1.76x September's proven pace so every lorry sells through in a week. The reality-check column holds sales at September's actual proven pace while still paying for a lorry every week: revenue and cost of GOODS SOLD only reflect what proven demand actually moves, so materials paid for but not yet sold do not appear as an expense, they sit in the warehouse as inventory (an asset, shown on the row below). That is why the reality-check net profit can look thin or negative in the early weeks even though real cash is not disappearing, it is converting into stock on the shelf, which is the whole point of building toward the 800,000 floor. Once sales catch up to the stock on hand, the accounting profit catches up too.
B54: E. PATH TO THE 800,000 STOCK FLOOR
B55: Measure | D55: Value
B56: Target standing stock floor (KES, materials basis) | E56: 800000
B57: Lorries needed to reach the floor (materials basis, 160,430 each) | E57: =E56/160430 -> 4.9865985
B58: Weeks to reach the floor, ordering one full lorry every week | E58: =E56/160430 -> 4.9865985
B60: About 5 weekly lorry orders (roughly one calendar month at this cadence) puts 800,000+ of Premium-mix stock into rotation. From that point on, the goal shifts from building the floor to maintaining it: reordering only as fast as stock actually sells, which by then should be much closer to weekly if the sales side of the plan has scaled alongside the stock side. Track the Restock Cadence logic against real sell-through data each month rather than committing to weekly by calendar date alone.
...

Sheet Production Capacity - 6 Ladies
B2: Can 6 production ladies handle this plan?
B3: Built from your September 2025 payment schedule: 15 named workers, paid per day worked, attendance ranging 0-12 workers/day. That schedule is a real record of how much this team produced per worker-day, which is what lets us test whether 6 dedicated ladies can keep up.
B5: A. WHAT THE SEPTEMBER PAYMENT SCHEDULE SHOWS
B6: Named workers on the payment schedule | C6: 15
B7: Total worker-days recorded across the month | C7: 235 | E7: sum of the 'workers present' column
B8: Average workers present on an active day | C8: 7.4 | E8: ranged 1 on short Saturdays to 12 on the busiest days
B9: Total KDQ bottles/units produced & sold that month (all 16 SKUs) | C9: 40654 | E9: from the KDQ Sept 2025 Sales tab
B11: Implied throughput: bottles produced per worker-day | C11: =C9/C7 -> 172.99574
B12: This blends every task the line does per bottle (wash, fill, cap, seal, label, wrap, pack into bales) across all 16 SKUs that were running in September. It is a real, whole-process rate, not a guess. It is the best available proxy since the payment schedule records days worked and KES paid, not a piece-rate per bale, so this workbook does not invent a per-bale wage figure that wasn't given.
B16: B. WHAT 6 DEDICATED LADIES CAN PRODUCE, AT THAT SAME RATE
B17: Measure | D17: Value
B18: Operating days per month (Sundays off) | D18: 26
B19: Worker-days per month (6 ladies) | D19: =6*D18 -> 156
B20: Projected monthly capacity (bottles) | D20: =D19*C11 -> 26987.336
B21: Projected weekly capacity (6 ladies x 6 days) | D21: =6*6*C11 -> 6227.8468
B23: C. CAPACITY vs DEMAND
B24: Comparison | D24: Value
B25: Kept-mix (Premium-only) full-month demand, bottles | D25: =SUMPRODUCT(('Premium-Only Mix vs September'!$D$6:$D$21)*('Premium-Only Mix vs September'!$E$6:$E$21)*(('Premium-Only Mix vs September'!$J$6:$J$21)="KEPT")) -> 30586
B26: 6 ladies' capacity as % of that demand | D26: =D20/D25 -> 0.88234278
B28: Lorry stock: bottles needing fill/pack/label | D28: ='Starting Stock - Lorry & Profit'!F13 -> 16045
B29: Operating days for 6 ladies to process the full lorry | D29: =D28/(6*C11) -> 15.457991
B30: Days for the same stock to sell out at Sept's pace | D30: ='Starting Stock - Lorry & Profit'!F27 -> 10.56581
B32: Two things point the same direction: 6 dedicated ladies come in at roughly 88% of the full Premium-only demand at September's blended pace, and processing one full lorry's stock takes them about 15-16 operating days, longer than the roughly 10-11 days it takes to sell that same stock. Production, not sales, is the real limit on how often you can restock. This supports the same restock-every-2.5-to-3-weeks recommendation on the Restock Cadence tab, and flags a small headcount or overtime buffer as the thing to watch if October demand runs above September's pace.

Sheet Capital, Cash Flow & Start
B2: Starting capital, cash flow & October 10 start
B3: 300,000 KES capital, split Jimal 200,000 / Diana 100,000. What it buys on day one, what's left as buffer, and the dated plan to get from today to first sale.
B5: A. STARTING CAPITAL
B6: Jimal's contribution | C6: 200000
B7: Diana's contribution | C7: 100000
B8: TOTAL STARTING CAPITAL | C8: =SUM(C6:C7) -> 300000
B10: B. FIRST OUTLAY (before any sales come in)
B11: Item | D11: Cost (KES)
B12: First lorry load of stock (materials, from Starting Stock tab) | C12: ='Starting Stock - Lorry & Profit'!G24 -> 160429.59
B13: Transport, Nairobi to Rongo (1 trip) | C13: 45000
B14: FIRST OUTLAY TOTAL | C14: =SUM(C12:C13) -> 205429.59
B15: CASH BUFFER REMAINING before first sales land | C15: =C8-C14 -> 94570.41
B16: This buffer covers the first days of payroll and overheads while the lorry's stock is still being filled and sold; it is not meant to sit idle. First-cycle sales (see Starting Stock tab) are projected at roughly 357,500 KES against a 163,000 KES lorry cost, so cash turns positive fast once selling starts.
B20: C. DATED PLAN: OPERATIONS START OCTOBER 10, 2026
B21: Date / window | C21: Action
B22: Now - Oct 3 | C22: Place the first lorry order (163,000 KES materials) with the Nairobi supplier so it ships in time to reach Rongo before Oct 10. Confirm the driver and transport booking (45,000 KES).
B23: Now - Oct 7 | C23: Complete the slight machine repairs flagged in the Warehouse Audit (not full maintenance, just enough to kickstart production). Confirm all 6 production ladies, the driver, sales person and accountant/manager are ready to start Oct 10.
B24: Oct 8 - 9 | C24: Lorry stock arrives in Rongo. Receive, count and store. Brief the team on the Premium-only SKU mix (no Platinum, no Grace, small Custom Premium runs only).
B25: Oct 10 | C25: Production and sales begin. Production ladies start filling/capping/labelling from the lorry stock; sales and driver start distribution same day.
B26: Oct 10 - ~20 | C26: First cycle: sell through the lorry stock (about 10-11 selling days at September's pace). Track daily sales against the Restock Cadence tab so the next order timing is based on real numbers, not the calendar.
B27: ~Oct 20 - 22 | C27: Place the second lorry order once cash from cycle 1 has come in, targeting the 2.5-3 week cadence recommended on the Restock Cadence tab rather than ordering weekly.
B28: Ongoing | C28: Recheck the Production Capacity tab monthly: if 6 ladies fall behind demand, that shows up as unsold gaps or late restocks before it shows up as a cash problem.

Sheet Profit Sharing Model
B2: Profit sharing model: Jimal and Diana
B3: Jimal brings the majority of the capital, runs the business full time on the ground in Rongo, and holds full decision-making control. Diana is a minority investor: capital only, occasional small tasks, not on-site. This tab lays out the waterfall from company profit to what each of you actually takes home.
B5: A. CAPITAL CONTRIBUTIONS
B6: Contributor | C6: Amount (KES) | D6: Share of capital | E6: Role
B7: Jimal | C7: 200000 | D7: =C7/C9 -> 0.66666667 | E7: Full operational control, on-ground manager, sole decision-maker
B8: Diana | C8: 100000 | D8: =C8/C9 -> 0.33333333 | E8: Minority investor, capital only, occasional small tasks, not on-site
B9: TOTAL CAPITAL | C9: =SUM(C7:C8) -> 300000
B11: B. MONTHLY PROFIT-SHARING WATERFALL
B12: Step | D12: KES
B13: NET COMPANY PROFIT (pre-sharing, from Weekly Restock tab, target scenario) | C13: ='Weekly Restock & Monthly P&L'!C46 -> 270350.86
B14: Retained to company accounts | C14: =C13*D14 -> 67587.716 | D14: 0.25
B15: Distributable to Jimal and Diana | C15: =C13-C14 -> 202763.15
B17: Retained company cash builds the reserve that funds the next weekly lorry order and the ramp toward the 800,000 stock floor, so it is not idle, it is the mechanism that makes weekly full-capacity reordering self-funding after the first few cycles. Edit the 25% if you want a faster or slower build to the floor.
B21: C. HOW TO SPLIT THE 75% BETWEEN JIMAL AND DIANA: THREE MODELS
B22: Model | C22: Jimal % | D22: Diana % | E22: Basis
B23: A. Capital pro-rata | C23: 0.667 | D23: 0.333 | E23: Matches the 200k:100k capital ratio exactly. Simplest to justify since Jimal's labor is already paid separately via the 80,000 stipend, so this slice is purely a return on capital.
B24: B. Control premium (recommended) | C24: 0.7 | D24: 0.3 | E24: Weights slightly beyond capital ratio because Jimal carries full decision-making authority and is the sole party bearing operational risk day to day, a role Diana is explicitly not taking on.
B25: C. Equal split | C25: 0.5 | D25: 0.5 | E25: Included for comparison only. Hard to justify here given unequal capital and unequal involvement; typically only fits when both parties contribute comparable capital and labor.
B28: D. CHOSEN SPLIT AND WORKED EXAMPLE (this month's target-scenario profit)
B29: Chosen split: Jimal % | C29: 0.7 | D29: Edit Jimal's % here (Diana's fills in automatically); defaults to Model B.
B30: Chosen split: Diana % | C30: =1-C29 -> 0.3
B32: Line item | D32: KES
B33: Company retained (25%) | C33: =C14 -> 67587.716
B34: Jimal's share of distributable 75% | C34: =C15*C29 -> 141934.2
B35: Diana's share of distributable 75% | C35: =C15*C30 -> 60828.944
B36: Jimal's monthly stipend (from New Team & Overheads tab) | C36: ='New Team & Overheads'!E33 -> 80000
B37: JIMAL'S TOTAL MONTHLY TAKE (stipend + profit share) | C37: =C34+C36 -> 221934.2
B38: DIANA'S TOTAL MONTHLY TAKE (profit share only, no stipend) | C38: =C35 -> 60828.944
B41: Recommended: Model B (70/30). Jimal's operational labor is already compensated separately through the 80,000 monthly stipend, so this 75% pool is really compensation for capital plus the extra weight of full decision-making authority and being the only party carrying operational risk day to day; that combination is what pushes it a little past the pure 66.7/33.3 capital ratio. If keeping things as simple and uncontestable as possible with Diana matters more than that extra weight, Model A (pure capital ratio) is the cleanest fallback and needs no justification beyond the amounts each of you put in. Either way, this is a business and financial structuring choice, not legal advice; put whichever split you settle on into a short written agreement with Diana before profit-sharing starts, the same way the wider family/investor structure in the Ownership Transfer advisory is being formalized.

Sheet Dashboard
B2: Dashboard: MARA WATER restart at a glance
B3: Every number below is a live link back to its source tab. Change an input anywhere in the workbook and this page updates with it.
B5: A. KEY NUMBERS
B6: Realistic monthly net profit (3 restocks/month, 65,000 stipend) | E6: Breakeven restocks/month (65,000 stipend) | H6: Minimum restocks/month for 300,000 profit (65,000 stipend) | K6: Cash buffer at October 10 start
B7: ='Starting Stock - Lorry & Profit'!E49 -> 118781.23 | E7: =('New Team & Overheads'!E24+65000)/('Weekly Restock & Monthly P&L'!E69*'Starting Stock - Lorry & Profit'!H24) -> 2.0491955 | H7: ='Weekly Restock & Monthly P&L'!D77 -> 5 | K7: ='Capital, Cash Flow & Start'!C15 -> 94570.41
B10: The 300,000 and 500,000 profit targets need 5 and 7 restock orders a month respectively, well beyond both proven sales pace and 6-lady production capacity today (see the Weekly Restock tab, Section F). Treat them as growth goals, not near-term plans; 3 restocks a month is the realistic target this dashboard is built around.
B13: B. NET PROFIT BY RESTOCK FREQUENCY (a full lorry every time)
B32: C. FIXED MONTHLY COST BREAKDOWN
B33: Cost block | C33: KES/month
B34: Payroll (driver, sales, accountant, 6 ladies) | C34: ='New Team & Overheads'!E11 -> 125000
B35: Overheads (fuel, electricity, repairs, printing etc.) | C35: ='New Team & Overheads'!E22 -> 66000
B36: Jimal's stipend (65,000 option) | C36: =65000 -> 65000
B50: D. DAILY SALES TARGET, BY PROFIT GOAL
B51: Scenario | C51: Daily sales target (KES)
B52: 300k @ 80k stipend | C52: ='Weekly Restock & Monthly P&L'!C78 -> 62854.574
B53: 300k @ 65k stipend | C53: ='Weekly Restock & Monthly P&L'!D78 -> 61203.403
B54: 500k @ 80k stipend | C54: ='Weekly Restock & Monthly P&L'!E78 -> 84870.187
B55: 500k @ 65k stipend | C55: ='Weekly Restock & Monthly P&L'!F78 -> 83219.016
B77: September's proven daily sales pace is about 33,854 KES/day for comparison; every bar above is a multiple of that, which is why Section F on the Weekly Restock tab treats 300,000 and 500,000 as stretch and long-horizon goals rather than near-term plans.
